<?xml version="1.0" encoding="UTF-8"?>
<testng-results skipped="0" failed="1" total="1" passed="0">
  <reporter-output>
  </reporter-output>
  <suite name="Default suite" duration-ms="500017" started-at="2015-04-03T23:59:55Z" finished-at="2015-04-04T00:08:15Z">
    <groups>
    </groups>
    <test name="Default test" duration-ms="500017" started-at="2015-04-03T23:59:55Z" finished-at="2015-04-04T00:08:15Z">
      <class name="com.ecofactorqa.awayapi.Set_Away_Valid">
        <test-method status="PASS" signature="init()[pri:0, instance:com.ecofactorqa.awayapi.Set_Away_Valid@7c868269]" name="init" is-config="true" duration-ms="112" started-at="2015-04-03T16:59:55Z" finished-at="2015-04-03T16:59:55Z">
          <reporter-output>
          </reporter-output>
        </test-method> <!-- init -->
        <test-method status="FAIL" signature="test_start_Away_using_valid_thermostatID_natural_end()[pri:0, instance:com.ecofactorqa.awayapi.Set_Away_Valid@7c868269]" name="test_start_Away_using_valid_thermostatID_natural_end" duration-ms="499884" started-at="2015-04-03T16:59:55Z" finished-at="2015-04-03T17:08:15Z">
          <exception class="java.lang.AssertionError">
            <message>
              <![CDATA[expected [0] but found [32753]]]>
            </message>
            <full-stacktrace>
              <![CDATA[java.lang.AssertionError: expected [0] but found [32753]
	at org.testng.Assert.fail(Assert.java:94)
	at org.testng.Assert.failNotEquals(Assert.java:494)
	at org.testng.Assert.assertEquals(Assert.java:123)
	at org.testng.Assert.assertEquals(Assert.java:370)
	at org.testng.Assert.assertEquals(Assert.java:380)
	at com.ecofactorqa.awayapi.Set_Away_Valid.test_start_Away_using_valid_thermostatID_natural_end(Set_Away_Valid.java:244)
	at sun.reflect.NativeMethodAccessorImpl.invoke0(Native Method)
	at sun.reflect.NativeMethodAccessorImpl.invoke(Unknown Source)
	at sun.reflect.DelegatingMethodAccessorImpl.invoke(Unknown Source)
	at java.lang.reflect.Method.invoke(Unknown Source)
	at org.testng.internal.MethodInvocationHelper.invokeMethod(MethodInvocationHelper.java:84)
	at org.testng.internal.Invoker.invokeMethod(Invoker.java:714)
	at org.testng.internal.Invoker.invokeTestMethod(Invoker.java:901)
	at org.testng.internal.Invoker.invokeTestMethods(Invoker.java:1231)
	at org.testng.internal.TestMethodWorker.invokeTestMethods(TestMethodWorker.java:127)
	at org.testng.internal.TestMethodWorker.run(TestMethodWorker.java:111)
	at org.testng.TestRunner.privateRun(TestRunner.java:767)
	at org.testng.TestRunner.run(TestRunner.java:617)
	at org.testng.SuiteRunner.runTest(SuiteRunner.java:334)
	at org.testng.SuiteRunner.runSequentially(SuiteRunner.java:329)
	at org.testng.SuiteRunner.privateRun(SuiteRunner.java:291)
	at org.testng.SuiteRunner.run(SuiteRunner.java:240)
	at org.testng.SuiteRunnerWorker.runSuite(SuiteRunnerWorker.java:52)
	at org.testng.SuiteRunnerWorker.run(SuiteRunnerWorker.java:86)
	at org.testng.TestNG.runSuitesSequentially(TestNG.java:1224)
	at org.testng.TestNG.runSuitesLocally(TestNG.java:1149)
	at org.testng.TestNG.run(TestNG.java:1057)
	at org.testng.remote.RemoteTestNG.run(RemoteTestNG.java:111)
	at org.testng.remote.RemoteTestNG.initAndRun(RemoteTestNG.java:204)
	at org.testng.remote.RemoteTestNG.main(RemoteTestNG.java:175)
]]>
            </full-stacktrace>
          </exception> <!-- java.lang.AssertionError -->
          <reporter-output>
          </reporter-output>
        </test-method> <!-- test_start_Away_using_valid_thermostatID_natural_end -->
      </class> <!-- com.ecofactorqa.awayapi.Set_Away_Valid -->
    </test> <!-- Default test -->
  </suite> <!-- Default suite -->
</testng-results>
