<?xml version="1.0" encoding="UTF-8"?>
<testng-results skipped="0" failed="1" total="1" passed="0">
  <reporter-output>
  </reporter-output>
  <suite name="Default suite" duration-ms="33384" started-at="2015-08-25T00:31:46Z" finished-at="2015-08-25T00:32:20Z">
    <groups>
    </groups>
    <test name="Default test" duration-ms="33384" started-at="2015-08-25T00:31:46Z" finished-at="2015-08-25T00:32:20Z">
      <class name="com.ecofactorqa.awayapi.Set_Away_Valid">
        <test-method status="PASS" signature="init()[pri:0, instance:com.ecofactorqa.awayapi.Set_Away_Valid@5d277b59]" name="init" is-config="true" duration-ms="109" started-at="2015-08-24T17:31:46Z" finished-at="2015-08-24T17:31:46Z">
          <reporter-output>
          </reporter-output>
        </test-method> <!-- init -->
        <test-method status="FAIL" signature="test_start_Away_using_valid_thermostatID_cancel_by_mo()[pri:0, instance:com.ecofactorqa.awayapi.Set_Away_Valid@5d277b59]" name="test_start_Away_using_valid_thermostatID_cancel_by_mo" duration-ms="33256" started-at="2015-08-24T17:31:46Z" finished-at="2015-08-24T17:32:20Z">
          <exception class="java.lang.AssertionError">
            <message>
              <![CDATA[Expected status 200. Actual status is :400 expected [true] but found [false]]]>
            </message>
            <full-stacktrace>
              <![CDATA[java.lang.AssertionError: Expected status 200. Actual status is :400 expected [true] but found [false]
	at org.testng.Assert.fail(Assert.java:94)
	at org.testng.Assert.failNotEquals(Assert.java:494)
	at org.testng.Assert.assertTrue(Assert.java:42)
	at com.ecofactorqa.awayapi.Set_Away_Valid.test_start_Away_using_valid_thermostatID_cancel_by_mo(Set_Away_Valid.java:163)
	at sun.reflect.NativeMethodAccessorImpl.invoke0(Native Method)
	at sun.reflect.NativeMethodAccessorImpl.invoke(Unknown Source)
	at sun.reflect.DelegatingMethodAccessorImpl.invoke(Unknown Source)
	at java.lang.reflect.Method.invoke(Unknown Source)
	at org.testng.internal.MethodInvocationHelper.invokeMethod(MethodInvocationHelper.java:84)
	at org.testng.internal.Invoker.invokeMethod(Invoker.java:714)
	at org.testng.internal.Invoker.invokeTestMethod(Invoker.java:901)
	at org.testng.internal.Invoker.invokeTestMethods(Invoker.java:1231)
	at org.testng.internal.TestMethodWorker.invokeTestMethods(TestMethodWorker.java:127)
	at org.testng.internal.TestMethodWorker.run(TestMethodWorker.java:111)
	at org.testng.TestRunner.privateRun(TestRunner.java:767)
	at org.testng.TestRunner.run(TestRunner.java:617)
	at org.testng.SuiteRunner.runTest(SuiteRunner.java:334)
	at org.testng.SuiteRunner.runSequentially(SuiteRunner.java:329)
	at org.testng.SuiteRunner.privateRun(SuiteRunner.java:291)
	at org.testng.SuiteRunner.run(SuiteRunner.java:240)
	at org.testng.SuiteRunnerWorker.runSuite(SuiteRunnerWorker.java:52)
	at org.testng.SuiteRunnerWorker.run(SuiteRunnerWorker.java:86)
	at org.testng.TestNG.runSuitesSequentially(TestNG.java:1224)
	at org.testng.TestNG.runSuitesLocally(TestNG.java:1149)
	at org.testng.TestNG.run(TestNG.java:1057)
	at org.testng.remote.RemoteTestNG.run(RemoteTestNG.java:111)
	at org.testng.remote.RemoteTestNG.initAndRun(RemoteTestNG.java:204)
	at org.testng.remote.RemoteTestNG.main(RemoteTestNG.java:175)
]]>
            </full-stacktrace>
          </exception> <!-- java.lang.AssertionError -->
          <reporter-output>
          </reporter-output>
        </test-method> <!-- test_start_Away_using_valid_thermostatID_cancel_by_mo -->
      </class> <!-- com.ecofactorqa.awayapi.Set_Away_Valid -->
    </test> <!-- Default test -->
  </suite> <!-- Default suite -->
</testng-results>
